2019/02/24 16:21:18 - root - WARNING - Invalid routing address
2019/02/24 16:22:49 - root - WARNING - Invalid routing address
2019/02/24 16:23:42 - root - WARNING - Invalid routing address
2019/02/24 16:24:10 - root - WARNING - Invalid routing address
2019/02/24 16:32:09 - root - ERROR - The routing application has errors
Traceback (most recent call last):
  File "E:\git\Dawn\dawn.py", line 42, in response_for_path
    return response(request)
  File "E:\git\Dawn\app.py", line 9, in hello
    print(c[7])
IndexError: list index out of range
2019/02/24 16:33:38 - root - ERROR - The routing application has errors
Traceback (most recent call last):
  File "E:\git\Dawn\dawn.py", line 41, in response_for_path
    return response(request)
  File "E:\git\Dawn\app.py", line 9, in hello
    print(c[7])
IndexError: list index out of range
2019/02/24 16:35:48 - root - WARNING - Invalid routing address /fewfew
2019/02/27 21:55:28 - root - WARNING - Invalid routing address None
2019/02/27 21:55:28 - root - WARNING - Invalid routing address None
2019/02/27 21:56:34 - root - WARNING - Invalid routing address None
2019/02/27 21:56:37 - root - WARNING - Invalid routing address None
2019/02/27 21:56:39 - root - WARNING - Invalid routing address None
2019/02/27 21:56:40 - root - WARNING - Invalid routing address None
2019/02/27 21:56:49 - root - WARNING - Invalid routing address None
2019/02/27 21:57:30 - root - WARNING - Invalid routing address None
2019/02/27 21:57:46 - root - WARNING - Invalid routing address None
2019/02/27 21:57:47 - root - WARNING - Invalid routing address None
2019/02/27 21:59:21 - root - WARNING - Invalid routing address /
2019/02/27 21:59:42 - root - WARNING - Invalid routing address /
2019/02/27 22:00:30 - root - WARNING - Invalid routing address /
2019/02/27 22:05:39 - root - WARNING - Invalid routing address None
2019/02/27 22:07:34 - root - WARNING - Invalid routing address None
2019/02/27 22:19:35 - root - WARNING - Invalid routing address None
2019/02/27 22:19:57 - root - WARNING - Invalid routing address None
2019/02/27 22:21:11 - root - WARNING - Invalid routing address None
2019/02/27 22:21:47 - root - WARNING - Invalid routing address None
2019/02/27 22:21:59 - root - WARNING - Invalid routing address None
2019/02/27 22:22:09 - root - WARNING - Invalid routing address None
2019/02/27 22:23:09 - root - WARNING - Invalid routing address None
2019/02/27 22:26:58 - root - WARNING - Invalid routing address None
2019/02/27 22:27:21 - root - WARNING - Invalid routing address None
2019/02/28 12:12:24 - root - WARNING - Invalid routing address None
2019/02/28 12:12:25 - root - WARNING - Invalid routing address None
2019/02/28 12:12:37 - root - WARNING - Invalid routing address None
2019/02/28 12:13:45 - root - WARNING - Invalid routing address None
2019/02/28 12:14:15 - root - WARNING - Invalid routing address None
2019/02/28 12:14:37 - root - WARNING - Invalid routing address None
2019/02/28 12:14:59 - root - WARNING - Invalid routing address None
2019/02/28 12:17:02 - root - ERROR - The routing application has errors
Traceback (most recent call last):
  File "E:\git\Dawn\dawn.py", line 65, in response_for_path
    return response(request, **kwarg)
  File "E:\git\Dawn\app.py", line 9, in hello
    print(c[7])
IndexError: list index out of range
2019/02/28 12:17:35 - root - ERROR - The routing application has errors
Traceback (most recent call last):
  File "E:\git\Dawn\dawn.py", line 65, in response_for_path
    return response(request, **kwarg)
  File "E:\git\Dawn\app.py", line 9, in hello
    print(c[7])
IndexError: list index out of range
2019/02/28 12:19:30 - root - ERROR - The routing application has errors
Traceback (most recent call last):
  File "E:\git\Dawn\dawn.py", line 65, in response_for_path
    return response(request, **kwarg)
  File "E:\git\Dawn\app.py", line 9, in hello
    print(c[7])
IndexError: list index out of range
2019/02/28 12:20:35 - root - ERROR - The routing application has errors
Traceback (most recent call last):
  File "E:\git\Dawn\dawn.py", line 66, in response_for_path
    return response(request, **kwarg)
  File "E:\git\Dawn\app.py", line 9, in hello
    print(c[7])
IndexError: list index out of range
2019/02/28 12:21:11 - root - ERROR - The routing application has errors
Traceback (most recent call last):
  File "E:\git\Dawn\dawn.py", line 66, in response_for_path
    return response(request, **kwarg)
  File "E:\git\Dawn\app.py", line 9, in hello
    print(c[7])
IndexError: list index out of range
2019/02/28 12:22:56 - root - WARNING - Invalid routing address None
2019/02/28 12:28:03 - root - WARNING - Invalid routing address None
2019/02/28 12:54:01 - root - WARNING - Invalid routing address None
